This is a testharness.js-based test.
PASS Service Worker: Cache.add and Cache.addAll 
FAIL Cache.add called with no arguments promise_test: Unhandled rejection with value: object "TypeError: undefined is not a function"
FAIL Cache.add called with relative URL specified as a string promise_test: Unhandled rejection with value: object "TypeError: undefined is not a function"
FAIL Cache.add called with non-HTTP/HTTPS URL promise_test: Unhandled rejection with value: object "TypeError: undefined is not a function"
FAIL Cache.add called with Request object promise_test: Unhandled rejection with value: object "TypeError: undefined is not a function"
FAIL Cache.add called with Request object with a used body promise_test: Unhandled rejection with value: object "TypeError: undefined is not a function"
FAIL Cache.add called twice with the same Request object promise_test: Unhandled rejection with value: object "TypeError: undefined is not a function"
FAIL Cache.add with request that results in a status of 404 promise_test: Unhandled rejection with value: object "TypeError: undefined is not a function"
FAIL Cache.add with request that results in a status of 500 promise_test: Unhandled rejection with value: object "TypeError: undefined is not a function"
FAIL Cache.addAll with no arguments promise_test: Unhandled rejection with value: object "TypeError: undefined is not a function"
FAIL Cache.addAll with a mix of valid and undefined arguments promise_test: Unhandled rejection with value: object "TypeError: undefined is not a function"
FAIL Cache.addAll with string URL arguments promise_test: Unhandled rejection with value: object "TypeError: undefined is not a function"
FAIL Cache.addAll with Request arguments promise_test: Unhandled rejection with value: object "TypeError: undefined is not a function"
FAIL Cache.addAll with a mix of succeeding and failing requests promise_test: Unhandled rejection with value: object "TypeError: undefined is not a function"
FAIL Cache.addAll called with the same Request object specified twice promise_test: Unhandled rejection with value: object "TypeError: undefined is not a function"
Harness: the test ran to completion.

